{DataVersion: 3465, size: [4, 4, 4], palette: [{Name: "gt_shanhai:quantum_parallel_processor", Properties: {formed: "true", light_level: "0", multiblocked: "true", powered: "true"}}, {Name: "gt_shanhai:quantum_computer_unit", Properties: {formed: "true", light_level: "12", multiblocked: "true", powered: "true"}}, {Name: "gt_shanhai:quantum_structure", Properties: {formed: "true", light_level: "0", multiblocked: "true", powered: "true"}}, {Name: "gt_shanhai:quantum_crafting_storage", Properties: {formed: "true", light_level: "0", multiblocked: "true", powered: "true"}}, {Name: "gt_shanhai:quantum_computer", Properties: {formed: "true", light_level: "12", multiblocked: "true", powered: "true"}}], blocks: [{pos: [0, 0, 0], state: 2}, {pos: [1, 0, 0], state: 2}, {pos: [2, 0, 0], state: 2}, {pos: [3, 0, 0], state: 2}, {pos: [0, 0, 1], state: 2}, {pos: [1, 0, 1], state: 2}, {pos: [2, 0, 1], state: 2}, {pos: [3, 0, 1], state: 2}, {pos: [0, 0, 2], state: 2}, {pos: [1, 0, 2], state: 2}, {pos: [2, 0, 2], state: 2}, {pos: [3, 0, 2], state: 2}, {pos: [0, 0, 3], state: 2}, {pos: [1, 0, 3], state: 2}, {pos: [2, 0, 3], state: 2}, {pos: [3, 0, 3], state: 2}, {pos: [0, 1, 0], state: 2}, {pos: [1, 1, 0], state: 2}, {pos: [2, 1, 0], state: 2}, {pos: [3, 1, 0], state: 2}, {pos: [0, 1, 1], state: 2}, {pos: [1, 1, 1], state: 0}, {pos: [2, 1, 1], state: 0}, {pos: [3, 1, 1], state: 2}, {pos: [0, 1, 2], state: 2}, {pos: [1, 1, 2], state: 0}, {pos: [2, 1, 2], state: 4}, {pos: [3, 1, 2], state: 2}, {pos: [0, 1, 3], state: 2}, {pos: [1, 1, 3], state: 2}, {pos: [2, 1, 3], state: 2}, {pos: [3, 1, 3], state: 2}, {pos: [0, 2, 0], state: 2}, {pos: [1, 2, 0], state: 2}, {pos: [2, 2, 0], state: 2}, {pos: [3, 2, 0], state: 2}, {pos: [0, 2, 1], state: 2}, {pos: [1, 2, 1], state: 1}, {pos: [2, 2, 1], state: 1}, {pos: [3, 2, 1], state: 2}, {pos: [0, 2, 2], state: 2}, {pos: [1, 2, 2], state: 3}, {pos: [2, 2, 2], state: 1}, {pos: [3, 2, 2], state: 2}, {pos: [0, 2, 3], state: 2}, {pos: [1, 2, 3], state: 2}, {pos: [2, 2, 3], state: 2}, {pos: [3, 2, 3], state: 2}, {pos: [0, 3, 0], state: 2}, {pos: [1, 3, 0], state: 2}, {pos: [2, 3, 0], state: 2}, {pos: [3, 3, 0], state: 2}, {pos: [0, 3, 1], state: 2}, {pos: [1, 3, 1], state: 2}, {pos: [2, 3, 1], state: 2}, {pos: [3, 3, 1], state: 2}, {pos: [0, 3, 2], state: 2}, {pos: [1, 3, 2], state: 2}, {pos: [2, 3, 2], state: 2}, {pos: [3, 3, 2], state: 2}, {pos: [0, 3, 3], state: 2}, {pos: [1, 3, 3], state: 2}, {pos: [2, 3, 3], state: 2}, {pos: [3, 3, 3], state: 2}], entities: []}